Workbook
Name EPICS_ESTIMATE: GITHUB_EPICS!$F$2:$F$62
Name EPICS_PERIOD: GITHUB_EPICS!$G$2:$G$62
Name EPICS_STATUS: GITHUB_EPICS!$D$2:$D$62
Name EPICS_TYPE: GITHUB_EPICS!$E$2:$E$62
Name PERIODS: Parameters!$A$6:$A$46
Name PLANNING: Parameters!$A$6:$J$12

Sheet Parameters
A1: Capacity planning for Alkemio
A2: This tab provides teams' velocity and overall releases capacity overview based on the current version of 2015 release calendar.
A4: Time Period | B4: Time Period Start | C4: Time Period End | D4: Features allocation, % | E4: Development Sprints available | F4: Vacations / Done (sprints) | G4: Available Sprints | H4: Points / sprint | I4: Capacity | J4: Comments
A6: 2023 Q1 | B6: 44928 | C6: 45012 | D6: 0.8 | E6: =(C6-B6)/7/2 -> 6 | F6: 6 | G6: =E6-F6 -> 0 | H6: 200 | I6: =H6*G6*D6 -> 0
A7: 2023 Q2 | B7: =C6 -> 45012 | C7: 45096 | D7: 0.8 | E7: =(C7-B7)/7/2 -> 6 | F7: 6 | G7: =E7-F7 -> 0 | H7: 200 | I7: =H7*G7*D7 -> 0 | M7: Note: update to have each period start / end adjustable
A8: 2023 Q3 | B8: =C7 -> 45096 | C8: 45194 | D8: 0.6 | E8: =(C8-B8)/7/2 -> 7 | F8: 5.5 | G8: =E8-F8 -> 1.5 | H8: 200 | I8: =H8*G8*D8 -> 180
A9: 2023 Q4 | B9: =C8 -> 45194 | C9: 45292 | D9: 0.5 | E9: =(C9-B9)/7/2 -> 7 | F9: 0.5 | G9: =E9-F9 -> 6.5 | H9: 200 | I9: =H9*G9*D9 -> 650
A10: 2024 Q1 | B10: =C9 -> 45292 | C10: 45383 | D10: 0.5 | E10: =(C10-B10)/7/2 -> 6.5 | F10: 0.5 | G10: =E10-F10 -> 6 | H10: 200 | I10: =H10*G10*D10 -> 600
A11: 2024 Q2 | B11: =C10 -> 45383 | C11: 45474 | D11: 0.5 | E11: =(C11-B11)/7/2 -> 6.5 | F11: 0.5 | G11: =E11-F11 -> 6 | H11: 200 | I11: =H11*G11*D11 -> 600
A12: 2024 H2 | B12: =C11 -> 45474 | C12: 45657 | D12: 0.5 | E12: =(C12-B12)/7/2 -> 13.071429 | G12: =E12-F12 -> 13.071429 | H12: 200 | I12: =H12*G12*D12 -> 1307.1429

Sheet Capacity
A4: Delivery | B4: Planned | C4: Available | D4: Done | E4: Total | F4: Functionality: Tactical | G4: Maintenance | H4: Operations: Security | I4: Operations: Effectiveness | J4: Usability | K4: Performance | L4: Functionality: Strategic | M4: Not specified
A5: 2023 Q1 | B5: =SUMIFS(EPICS_ESTIMATE, EPICS_PERIOD, $A5, EPICS_STATUS, "<>Done") -> 0 | C5: =Parameters!I6 -> 0 | D5: =SUMIFS(EPICS_ESTIMATE, EPICS_PERIOD, $A5, EPICS_STATUS, "Done") -> 0 | E5: =SUM(#REF!, #REF!) -> #REF! | F5: =SUMIFS(EPICS_ESTIMATE, EPICS_PERIOD, $A5, EPICS_TYPE, F$4) -> 0 | G5: =SUMIFS(EPICS_ESTIMATE, EPICS_PERIOD, $A5, EPICS_TYPE, G$4) -> 0 | H5: =SUMIFS(EPICS_ESTIMATE, EPICS_PERIOD, $A5, EPICS_TYPE, H$4) -> 0 | I5: =SUMIFS(EPICS_ESTIMATE, EPICS_PERIOD, $A5, EPICS_TYPE, I$4) -> 0 | J5: =SUMIFS(EPICS_ESTIMATE, EPICS_PERIOD, $A5, EPICS_TYPE, J$4) -> 0 | K5: =SUMIFS(EPICS_ESTIMATE, EPICS_PERIOD, $A5, EPICS_TYPE, K$4) -> 0 | L5: =SUMIFS(EPICS_ESTIMATE, EPICS_PERIOD, $A5, EPICS_TYPE, L$4) -> 0 | M5: =#REF!-SUM(F5:L5) -> #REF!
A6: 2023 Q2 | B6: =SUMIFS(EPICS_ESTIMATE, EPICS_PERIOD, $A6, EPICS_STATUS, "<>Done") -> 0 | C6: =Parameters!I7 -> 0 | D6: =SUMIFS(EPICS_ESTIMATE, EPICS_PERIOD, $A6, EPICS_STATUS, "Done") -> 0 | E6: =SUM(#REF!, #REF!) -> #REF! | F6: =SUMIFS(EPICS_ESTIMATE, EPICS_PERIOD, $A6, EPICS_TYPE, F$4) -> 0 | G6: =SUMIFS(EPICS_ESTIMATE, EPICS_PERIOD, $A6, EPICS_TYPE, G$4) -> 0 | H6: =SUMIFS(EPICS_ESTIMATE, EPICS_PERIOD, $A6, EPICS_TYPE, H$4) -> 0 | I6: =SUMIFS(EPICS_ESTIMATE, EPICS_PERIOD, $A6, EPICS_TYPE, I$4) -> 0 | J6: =SUMIFS(EPICS_ESTIMATE, EPICS_PERIOD, $A6, EPICS_TYPE, J$4) -> 0 | K6: =SUMIFS(EPICS_ESTIMATE, EPICS_PERIOD, $A6, EPICS_TYPE, K$4) -> 0 | L6: =SUMIFS(EPICS_ESTIMATE, EPICS_PERIOD, $A6, EPICS_TYPE, L$4) -> 0 | M6: =#REF!-SUM(F6:L6) -> #REF!
A7: =Parameters!A8 -> 2023 Q3 | B7: =SUMIFS(EPICS_ESTIMATE, EPICS_PERIOD, $A7, EPICS_STATUS, "<>Done") -> 0 | C7: =Parameters!I8 -> 180 | D7: =SUMIFS(EPICS_ESTIMATE, EPICS_PERIOD, $A7, EPICS_STATUS, "Done") -> 0 | E7: =SUM(#REF!, #REF!) -> #REF! | F7: =SUMIFS(EPICS_ESTIMATE, EPICS_PERIOD, $A7, EPICS_TYPE, F$4) -> 0 | G7: =SUMIFS(EPICS_ESTIMATE, EPICS_PERIOD, $A7, EPICS_TYPE, G$4) -> 0 | H7: =SUMIFS(EPICS_ESTIMATE, EPICS_PERIOD, $A7, EPICS_TYPE, H$4) -> 0 | I7: =SUMIFS(EPICS_ESTIMATE, EPICS_PERIOD, $A7, EPICS_TYPE, I$4) -> 0 | J7: =SUMIFS(EPICS_ESTIMATE, EPICS_PERIOD, $A7, EPICS_TYPE, J$4) -> 0 | K7: =SUMIFS(EPICS_ESTIMATE, EPICS_PERIOD, $A7, EPICS_TYPE, K$4) -> 0 | L7: =SUMIFS(EPICS_ESTIMATE, EPICS_PERIOD, $A7, EPICS_TYPE, L$4) -> 0 | M7: =#REF!-SUM(F7:L7) -> #REF!
A8: =Parameters!A9 -> 2023 Q4 | B8: =SUMIFS(EPICS_ESTIMATE, EPICS_PERIOD, $A8, EPICS_STATUS, "<>Done") -> 0 | C8: =Parameters!I9 -> 650 | D8: =SUMIFS(EPICS_ESTIMATE, EPICS_PERIOD, $A8, EPICS_STATUS, "Done") -> 0 | E8: =SUM(#REF!, #REF!) -> #REF! | F8: =SUMIFS(EPICS_ESTIMATE, EPICS_PERIOD, $A8, EPICS_TYPE, F$4) -> 0 | G8: =SUMIFS(EPICS_ESTIMATE, EPICS_PERIOD, $A8, EPICS_TYPE, G$4) -> 0 | H8: =SUMIFS(EPICS_ESTIMATE, EPICS_PERIOD, $A8, EPICS_TYPE, H$4) -> 0 | I8: =SUMIFS(EPICS_ESTIMATE, EPICS_PERIOD, $A8, EPICS_TYPE, I$4) -> 0 | J8: =SUMIFS(EPICS_ESTIMATE, EPICS_PERIOD, $A8, EPICS_TYPE, J$4) -> 0 | K8: =SUMIFS(EPICS_ESTIMATE, EPICS_PERIOD, $A8, EPICS_TYPE, K$4) -> 0 | L8: =SUMIFS(EPICS_ESTIMATE, EPICS_PERIOD, $A8, EPICS_TYPE, L$4) -> 0 | M8: =#REF!-SUM(F8:L8) -> #REF!
A9: 2024 Q1 | B9: =SUMIFS(EPICS_ESTIMATE, EPICS_PERIOD, $A9, EPICS_STATUS, "<>Done") -> 0 | C9: =Parameters!I10 -> 600 | D9: =SUMIFS(EPICS_ESTIMATE, EPICS_PERIOD, $A9, EPICS_STATUS, "Done") -> 0 | E9: =SUM(#REF!, #REF!) -> #REF! | F9: =SUMIFS(EPICS_ESTIMATE, EPICS_PERIOD, $A9, EPICS_TYPE, F$4) -> 0 | G9: =SUMIFS(EPICS_ESTIMATE, EPICS_PERIOD, $A9, EPICS_TYPE, G$4, EPICS_STATUS, "<>Done") -> 0 | H9: =SUMIFS(EPICS_ESTIMATE, EPICS_PERIOD, $A9, EPICS_TYPE, H$4, EPICS_STATUS, "<>Done") -> 0 | I9: =SUMIFS(EPICS_ESTIMATE, EPICS_PERIOD, $A9, EPICS_TYPE, I$4, EPICS_STATUS, "<>Done") -> 0 | J9: =SUMIFS(EPICS_ESTIMATE, EPICS_PERIOD, $A9, EPICS_TYPE, J$4, EPICS_STATUS, "<>Done") -> 0 | K9: =SUMIFS(EPICS_ESTIMATE, EPICS_PERIOD, $A9, EPICS_TYPE, K$4, EPICS_STATUS, "<>Done") -> 0 | L9: =SUMIFS(EPICS_ESTIMATE, EPICS_PERIOD, $A9, EPICS_TYPE, L$4, EPICS_STATUS, "<>Done") -> 0 | M9: =#REF!-SUM(F9:L9) -> #REF!
A10: 2024 Q2 | B10: =SUMIFS(EPICS_ESTIMATE, EPICS_PERIOD, $A10, EPICS_STATUS, "<>Done") -> 0 | C10: =Parameters!I10 -> 600 | D10: =SUMIFS(EPICS_ESTIMATE, EPICS_PERIOD, $A10, EPICS_STATUS, "Done") -> 0 | E10: =SUM(#REF!, #REF!) -> #REF! | F10: =SUMIFS(EPICS_ESTIMATE, EPICS_PERIOD, $A10, EPICS_TYPE, F$4) -> 0 | G10: =SUMIFS(EPICS_ESTIMATE, EPICS_PERIOD, $A10, EPICS_TYPE, G$4, EPICS_STATUS, "<>Done") -> 0 | H10: =SUMIFS(EPICS_ESTIMATE, EPICS_PERIOD, $A10, EPICS_TYPE, H$4, EPICS_STATUS, "<>Done") -> 0 | I10: =SUMIFS(EPICS_ESTIMATE, EPICS_PERIOD, $A10, EPICS_TYPE, I$4, EPICS_STATUS, "<>Done") -> 0 | J10: =SUMIFS(EPICS_ESTIMATE, EPICS_PERIOD, $A10, EPICS_TYPE, J$4, EPICS_STATUS, "<>Done") -> 0 | K10: =SUMIFS(EPICS_ESTIMATE, EPICS_PERIOD, $A10, EPICS_TYPE, K$4, EPICS_STATUS, "<>Done") -> 0 | L10: =SUMIFS(EPICS_ESTIMATE, EPICS_PERIOD, $A10, EPICS_TYPE, L$4, EPICS_STATUS, "<>Done") -> 0 | M10: =#REF!-SUM(F10:L10) -> #REF!
A11: =Parameters!A12 -> 2024 H2 | B11: =SUMIFS(EPICS_ESTIMATE, EPICS_PERIOD, $A11, EPICS_STATUS, "<>Done") -> 0 | C11: =Parameters!I12 -> 1307.1429 | D11: =SUMIFS(EPICS_ESTIMATE, EPICS_PERIOD, $A11, EPICS_STATUS, "Done") -> 0 | E11: =SUM(#REF!, #REF!) -> #REF! | F11: =SUMIFS(EPICS_ESTIMATE, EPICS_PERIOD, $A11, EPICS_TYPE, F$4) -> 0 | G11: =SUMIFS(EPICS_ESTIMATE, EPICS_PERIOD, $A11, EPICS_TYPE, G$4, EPICS_STATUS, "<>Done") -> 0 | H11: =SUMIFS(EPICS_ESTIMATE, EPICS_PERIOD, $A11, EPICS_TYPE, H$4, EPICS_STATUS, "<>Done") -> 0 | I11: =SUMIFS(EPICS_ESTIMATE, EPICS_PERIOD, $A11, EPICS_TYPE, I$4, EPICS_STATUS, "<>Done") -> 0 | J11: =SUMIFS(EPICS_ESTIMATE, EPICS_PERIOD, $A11, EPICS_TYPE, J$4, EPICS_STATUS, "<>Done") -> 0 | K11: =SUMIFS(EPICS_ESTIMATE, EPICS_PERIOD, $A11, EPICS_TYPE, K$4, EPICS_STATUS, "<>Done") -> 0 | L11: =SUMIFS(EPICS_ESTIMATE, EPICS_PERIOD, $A11, EPICS_TYPE, L$4, EPICS_STATUS, "<>Done") -> 0 | M11: =#REF!-SUM(F11:L11) -> #REF!

Sheet GITHUB_EPICS
A1: Assignees | B1: Repository | C1: Labels | D1: Title | E1: Status | F1: Sprint | G1: Milestone | H1: Period | I1: EpicPoints | J1: Partner | K1: SprintPoints | L1: Milestone
B2: alkemio | C2: Epic | D2: Client Tech debt: Q4 2025 | E2: Being defined
B3: alkemio | C3: Epic | D3: Working on Alkemio as an Organization | E3: Being defined | F3: 2025-10-28
A4: Evgeni Dimitrov | B4: alkemio | C4: Epic,QA | D4: QA: Test Suites extensions Q4 | E4: Being defined | G4: Improved Confidence in the Platform | H4: 2024 Q3
B5: alkemio | C5: Epic | D5: Whiteboards: Robustness + performance Q4 | E5: Being defined | G5: Improved Confidence in the Platform
B6: alkemio | C6: Epic,QA,Product Discussion,Rhea Team | D6: QA on multi-user collaboration on whiteboard | E6: Being defined | F6: 2025-10-28 | G6: Improved Confidence in the Platform | H6: 2024 Q2 | K6: 13
A7: Svetoslav Petkov,user | B7: alkemio | C7: Epic | D7: Reporting: (automated) sharing of reports , read only access | E7: Being defined | H7: 2024 Q2 | I7: 20
B8: alkemio | C8: Epic,Roadmap Candidate | D8: Client component library in Figma | E8: Being defined | H8: 2024 Q2 | K8: 8
B9: alkemio | C9: Epic | D9: Simpler URLs | E9: Being defined | G9: Spaces with Subspaces | H9: 2024 Q3
A10: Valentin Yanakiev | B10: alkemio | C10: Epic,Infrastructure | D10: Storage management | E10: Being defined | F10: 2025-10-28 | H10: 2024 Q3
B11: alkemio | C11: Initiative | D11: I: Analytics via connectivity graph v1 | E11: Being defined
B12: alkemio | C12: Initiative | D12: I: Maintainability | E12: Being defined
B13: alkemio | C13: Initiative | D13: I: Journey structure refresh | E13: Being defined | F13: 2023-03-14
B14: alkemio | C14: Initiative | D14: Innovation library - Agreements | E14: Being defined
B15: alkemio | C15: Initiative | D15: I: Onboarding the community | E15: Being defined
B16: alkemio | C16: Initiative | D16: I: Innovation Hubs | E16: Being defined
B17: alkemio | C17: Initiative | D17: I: Platform responsiveness | E17: Being defined
B18: alkemio | C18: Initiative | D18: I: Guidance for users | E18: Being defined
B19: alkemio | C19: Initiative | D19: I: Platform Management | E19: Being defined
B20: alkemio | C20: Initiative | D20: I: Accessibility | E20: Being defined
B21: alkemio | C21: Initiative | D21: I: Content + Knowledge Management | E21: Being defined
B22: alkemio | C22: Initiative | D22: I: Notifications | E22: Being defined
B23: alkemio | C23: Initiative | D23: I: Library population, usage + feedback | E23: Being defined
B24: alkemio | C24: Initiative | D24: Content on the platform | E24: Being defined
B25: alkemio | C25: Initiative | D25: I: Innovation Library | E25: Being defined
... B29: alkemio | C29: Epic | D29: Bucket: Enhancing UX: Visual improvements | E29: Being defined
A30: Bobby Kolev | B30: alkemio | C30: Epic | D30: Video calling services | E30: Being elaborated | F30: 2025-09-16
A31: Bobby Kolev,Svetoslav Petkov | B31: alkemio | C31: Epic | D31: Notifications: Controls per space | E31: Being elaborated | F31: 2025-10-14 | G31: Notifications: on the platform, per space | H31: 2024 Q2
B32: alkemio | C32: Epic | D32: Notifications: Grouping + additional types | E32: Being elaborated | F32: 2025-10-28 | G32: Notifications: on the platform, per space | H32: 2024 Q2 | I32: 50
A33: Polina Boneva | B33: alkemio | C33: Epic,client | D33: Accessibility: WCAG 2.1 | E33: Being elaborated | F33: 2025-09-30
B34: alkemio | C34: Epic | D34: Templates: Interaction Space library and platform library | E34: Being elaborated | F34: 2025-09-16 | G34: Templates: Complete set | H34: 2024 Q2 | I34: 30
A35: Valentin Yanakiev | B35: alkemio | C35: Epic | D35: Sharing/Collaborating in callouts with unauthenticated users | E35: Being elaborated | F35: 2025-09-16
A36: Valentin Yanakiev | B36: alkemio | C36: Epic,Atlas Team,Rhea Team | D36: Independent issues | E36: Being elaborated | F36: 2025-09-16
B37: alkemio | C37: Epic | D37: Calendar events Bucket: Importing/Exporting; flexible time; show events from related sub/space | E37: Being elaborated | F37: 2025-10-14 | H37: 2024 Q3
B38: infrastructure-operations | C38: operations,Epic,Infrastructure | D38: External Penetration Testing [Q4 2025] | E38: Being elaborated | F38: 2025-10-14 | J38: Avans
B39: alkemio | C39: Epic | D39: Subscriptions on all Space pages | E39: Being elaborated | F39: 2025-10-28
B40: alkemio | C40: Epic,Roadmap Discussion,New this Sprint | D40: Licensing: Account management | E40: Being elaborated | F40: 2025-10-14 | G40: Products + Licensing
B41: alkemio | C41: Epic | D41: Flexible & Templatable community roles | E41: Being elaborated | G41: Innovation Professional Support | H41: 2024 Q2 | I41: 30
B42: alkemio | C42: Epic | D42: VC: Single user interaction | E42: Being elaborated
B43: alkemio | C43: Epic,Product Team | D43: Space layout | E43: Being elaborated | F43: 2025-10-28
...
